Workbook

Sheet KASENGA
A1: COLLECTE RAPIDE DES DONNEES STATISTIQUES SCOLAIRES DES PARAMETRES ESSENTIELS
A2: TABLEAU SYNTHESE
A3: SOUS-DIVISION EDUCATIONNELLE :…………………………………………………………………………………. | D3: KASENGA
A4: PROVINCE EDUCATIONNELLE :…………………………………………………………………………………. | D4: HAUT-KATANGA 2
A5: PROVINCE ADMINISTRATIVE :…………………………………………………………………………………. | D5: HAUT-KATANGA
A6: Tableau 1 : Nombre d’Etablissements scolaires par Niveau d’enseignement et Regime de Gestion
A7: N° | B7: Niveau d’enseignement et Régime de Gestion | C7: PRE-PRIMAIRE | D7: PRIMAIRE | E7: SECONDAIRE | F7: TOTAL
A9: 1 | B9: ENC | C9: 0 | D9: 17 | E9: 13 | F9: 30
A10: 2 | B10: ECC | C10: 4 | D10: 77 | E10: 40 | F10: 121
A11: 3 | B11: ECP | C11: 0 | D11: 87 | E11: 48 | F11: 135
A12: 4 | B12: ECK | C12: 0 | D12: 1 | E12: 0 | F12: 1
A13: 5 | B13: ECBAPT | C13: 0 | D13: 0 | E13: 1 | F13: 1
A14: 6 | B14: ECADV | C14: 0 | D14: 1 | E14: 1 | F14: 2
A15: 7 | B15: PRIVEE | C15: 1 | D15: 5 | E15: 3 | F15: 9
A16: TOTAL | C16: =SUM(C9:C15) -> 5 | D16: =SUM(D9:D15) -> 188 | E16: =SUM(E9:E15) -> 106 | F16: =SUM(F9:F15) -> 299
A18: ENSEIGNEMENT PRE-PRIMAIRE
A19: Tableau 2 : Nombre de classes organisées par année d’études et regime de gestion
A20: N° | B20: Niveau d’enseignement et Régime de Gestion | C20: 1ère année | D20: 2è année | E20: 3è annnée | F20: TOTAL
A21: 1 | B21: ENC | C21: 0 | D21: 0 | E21: 0 | F21: 0
A22: 2 | B22: ECC | C22: 4 | D22: 4 | E22: 4 | F22: 12
A23: 3 | B23: ECP | C23: 0 | D23: 0 | E23: 0 | F23: 0
A24: 4 | B24: ECK | C24: 0 | D24: 0 | E24: 0 | F24: 0
A25: 5 | B25: ECBAPT | C25: 0 | D25: 0 | E25: 0 | F25: 0
A26: 6 | B26: ECADV | C26: 0 | D26: 0 | E26: 0 | F26: 0
A27: 7 | B27: PRIVEE | C27: 1 | D27: 1 | E27: 1 | F27: 3
A28: TOTAL | C28: =SUM(C21:C27) -> 5 | D28: =SUM(D21:D27) -> 5 | E28: =SUM(E21:E27) -> 5 | F28: =SUM(F21:F27) -> 15
A30: Tableau 3 : Enfants inscrits par année d’études, sexe et regime de gestion
A31: N° | B31: Niveau d’enseignement et Régime de Gestion | C31: 1ère Année | E31: 2è Année | G31: 3è Année | I31: TOTAL
C32: G | D32: F | E32: G | F32: F | G32: G | H32: F | I32: G | J32: F | K32: GF
A33: 1 | B33: ENC | C33: 0 | D33: 0 | F33: 0 | G33: 0 | H33: 0 | I33: =G33+E33+C33 -> 0 | J33: =H33+F33+D33 -> 0 | K33: =J33+I33 -> 0
A34: 2 | B34: ECC | C34: 49 | D34: 57 | E34: 53 | F34: 55 | G34: 45 | H34: 49 | I34: =G34+E34+C34 -> 147 | J34: =H34+F34+D34 -> 161 | K34: =J34+I34 -> 308
A35: 3 | B35: ECP | C35: 0 | D35: 0 | E35: 0 | F35: 0 | G35: 0 | H35: 0 | I35: =G35+E35+C35 -> 0 | J35: =H35+F35+D35 -> 0 | K35: =J35+I35 -> 0
A36: 4 | B36: ECK | C36: 0 | D36: 0 | E36: 0 | F36: 0 | G36: 0 | H36: 0 | I36: =G36+E36+C36 -> 0 | J36: =H36+F36+D36 -> 0 | K36: =J36+I36 -> 0
A37: 5 | B37: ECBAPT | C37: 0 | D37: 0 | E37: 0 | F37: 0 | G37: 0 | H37: 0 | I37: =G37+E37+C37 -> 0 | J37: =H37+F37+D37 -> 0 | K37: =J37+I37 -> 0
A38: 6 | B38: ECADV | C38: 0 | D38: 0 | E38: 0 | F38: 0 | G38: 0 | H38: 0 | I38: =G38+E38+C38 -> 0 | J38: =H38+F38+D38 -> 0 | K38: =J38+I38 -> 0
A39: 7 | B39: PRIVEE | C39: 5 | D39: 4 | E39: 3 | F39: 2 | G39: 1 | H39: 3 | I39: =G39+E39+C39 -> 9 | J39: =H39+F39+D39 -> 9 | K39: =J39+I39 -> 18 | BL39: G | BN39: F | BO39: G | BP39: F | BQ39: G+F
A40: TOTAL | C40: =SUM(C33:C39) -> 54 | D40: =SUM(D33:D39) -> 61 | E40: =SUM(E33:E39) -> 56 | F40: =SUM(F33:F39) -> 57 | G40: =SUM(G33:G39) -> 46 | H40: =SUM(H33:H39) -> 52 | I40: =SUM(I33:I39) -> 156 | J40: =SUM(J33:J39) -> 170 | K40: =SUM(K33:K39) -> 326
A42: Tableau 4 : Educateurs (trices) par qualification, sexe et régime de gestion
A43: N° | B43: Niveau d’enseignement et Régime de Gestion | C43: EAP, D3 | E43: D4 | G43: EM | I43: D6 | K43: AUTRE | M43: TOTAL
C44: H | D44: F | E44: H | F44: F | G44: H | H44: F | I44: H | J44: F | K44: H | L44: F | M44: H | N44: F | O44: HF
...

Sheet KILWA
A1: COLLECTE RAPIDE DES DONNEES STATISTIQUES SCOLAIRES DES PARAMETRES ESSENTIELS
A2: TABLEAU SYNTHESE
A3: SOUS-DIVISION EDUCATIONNELLE :…………………………………………………………………………………. | D3: KILWA
A4: PROVINCE EDUCATIONNELLE :…………………………………………………………………………………. | D4: HAUT-KATANGA 2
A5: PROVINCE ADMINISTRATIVE :…………………………………………………………………………………. | D5: HAUT-KATANGA
A6: Tableau 1 : Nombre d’Etablissements scolaires par Niveau d’enseignement et Regime de Gestion
A7: N° | B7: Niveau d’enseignement et Régime de Gestion | C7: PRE-PRIMAIRE | D7: PRIMAIRE | E7: SECONDAIRE | F7: TOTAL
A8: 1 | B8: ENC | C8: 0 | D8: 11 | E8: 11 | F8: =SUM(C8:E8) -> 22
A9: 2 | B9: ECC | C9: 1 | D9: 51 | E9: 23 | F9: =SUM(C9:E9) -> 75
A10: 3 | B10: ECP | C10: 1 | D10: 71 | E10: 37 | F10: =SUM(C10:E10) -> 109
A11: 4 | B11: ECK | C11: 0 | D11: 3 | E11: 2 | F11: =SUM(C11:E11) -> 5
A12: 5 | B12: ECBAPT | C12: 0 | D12: 0 | E12: 0 | F12: =SUM(C12:E12) -> 0
A13: 6 | B13: ECADV | C13: 0 | D13: 1 | E13: 1 | F13: =SUM(C13:E13) -> 2
A14: 7 | B14: PRIVEE | C14: 0 | D14: 0 | E14: 0 | F14: =SUM(C14:E14) -> 0
A15: TOTAL | C15: =SUM(C8:C14) -> 2 | D15: =SUM(D8:D14) -> 137 | E15: =SUM(E8:E14) -> 74 | F15: =SUM(F8:F14) -> 213
A17: ENSEIGNEMENT PRE-PRIMAIRE
A18: Tableau 2 : Nombre de classes organisées par année d’études et regime de gestion
A19: N° | B19: Niveau d’enseignement et Régime de Gestion | C19: 1ère année | D19: 2è année | E19: 3è annnée | F19: TOTAL
A20: 1 | B20: ENC | C20: 0 | D20: 0 | E20: 0 | F20: =SUM(C20:E20) -> 0
A21: 2 | B21: ECC | C21: 2 | D21: 1 | E21: 1 | F21: =SUM(C21:E21) -> 4
A22: 3 | B22: ECP | C22: 2 | D22: 2 | E22: 0 | F22: =SUM(C22:E22) -> 4
A23: 4 | B23: ECK | C23: 0 | D23: 0 | E23: 0 | F23: 0
A24: 5 | B24: ECBAPT | C24: 0 | D24: 0 | E24: 0 | F24: 0
A25: 6 | B25: ECADV | C25: 0 | D25: 0 | E25: 0 | F25: 0
A26: 7 | B26: PRIVEE | C26: 0 | D26: 0 | E26: 0 | F26: 0
A27: TOTAL | C27: =SUM(C20:C26) -> 4 | D27: =SUM(D20:D26) -> 3 | E27: =SUM(E20:E26) -> 1 | F27: =SUM(F20:F26) -> 8
A29: Tableau : Enfants inscrits par année d’études, sexe et regime de gestion
A30: N° | B30: Niveau d’enseignement et Régime de Gestion | C30: 1ère Année | E30: 2è Année | G30: 3è Année | I30: TOTAL
C31: G | D31: F | E31: G | F31: F | G31: G | H31: F | I31: G | J31: F | K31: GF
A32: 1 | B32: ENC | C32: 0 | D32: 0 | E32: 0 | F32: 0 | G32: 0 | H32: 0 | I32: =G32+E32+C32 -> 0 | J32: =H32+F32+D32 -> 0 | K32: =J32+I32 -> 0
A33: 2 | B33: ECC | C33: 15 | D33: 17 | E33: 13 | F33: 18 | G33: 0 | H33: 0 | I33: =G33+E33+C33 -> 28 | J33: =H33+F33+D33 -> 35 | K33: =J33+I33 -> 63
A34: 3 | B34: ECP | C34: 8 | D34: 10 | E34: 7 | F34: 5 | G34: 9 | H34: 4 | I34: =G34+E34+C34 -> 24 | J34: =H34+F34+D34 -> 19 | K34: =J34+I34 -> 43
A35: 4 | B35: ECK | C35: 0 | D35: 0 | E35: 0 | F35: 0 | G35: 0 | H35: 0 | I35: =G35+E35+C35 -> 0 | J35: =H35+F35+D35 -> 0 | K35: =J35+I35 -> 0
A36: 5 | B36: ECBAPT | C36: 0 | D36: 0 | E36: 0 | F36: 0 | G36: 0 | H36: 0 | I36: =G36+E36+C36 -> 0 | J36: =H36+F36+D36 -> 0 | K36: =J36+I36 -> 0
A37: 6 | B37: ECADV | C37: 0 | D37: 0 | E37: 0 | F37: 0 | G37: 0 | H37: 0 | I37: =G37+E37+C37 -> 0 | J37: =H37+F37+D37 -> 0 | K37: =J37+I37 -> 0
A38: 7 | B38: PRIVEE | C38: 0 | D38: 0 | E38: 0 | F38: 0 | G38: 0 | H38: 0 | I38: =G38+E38+C38 -> 0 | J38: =H38+F38+D38 -> 0 | K38: =J38+I38 -> 0
A39: TOTAL | C39: =SUM(C32:C38) -> 23 | D39: =SUM(D32:D38) -> 27 | E39: =SUM(E32:E38) -> 20 | F39: =SUM(F32:F38) -> 23 | G39: =SUM(G32:G38) -> 9 | H39: =SUM(H32:H38) -> 4 | I39: =SUM(I32:I38) -> 52 | J39: =SUM(J32:J38) -> 54 | K39: =SUM(K32:K38) -> 106
A41: Tableau 4 : Educateurs (trices) par qualification, sexe et régime de gestion
A42: N° | B42: Niveau d’enseignement et Régime de Gestion | C42: EAP, D3 | E42: D4 | G42: EM | I42: D6 | K42: AUTRE | M42: TOTAL
C43: H | D43: F | E43: H | F43: F | G43: H | H43: F | I43: H | J43: F | K43: H | L43: F | M43: H | N43: F | O43: HF
...

Sheet MITWABA
A1: COLLECTE RAPIDE DES DONNEES STATISTIQUES SCOLAIRES DES PARAMETRES ESSENTIELS
A2: TABLEAU SYNTHESE
A3: SOUS-DIVISION EDUCATIONNELLE :…………………………………………………………………………………. | D3: MITWABA
A4: PROVINCE EDUCATIONNELLE :…………………………………………………………………………………. | D4: HAUT-KATANGA 2
A5: PROVINCE ADMINISTRATIVE :…………………………………………………………………………………. | D5: HAUT-KATANGA
A6: Tableau 1 : Nombre d’Etablissements scolaires par Niveau d’enseignement et Regime de Gestion
A7: N° | B7: Niveau d’enseignement et Régime de Gestion | C7: PRE-PRIMAIRE | D7: PRIMAIRE | E7: SECONDAIRE | F7: TOTAL
A8: 1 | B8: ENC | C8: 3 | D8: 29 | E8: 24 | F8: =SUM(C8:E8) -> 56
A9: 2 | B9: ECC | C9: 1 | D9: 78 | E9: 24 | F9: =SUM(C9:E9) -> 103
A10: 3 | B10: ECP | C10: 1 | D10: 46 | E10: 13 | F10: =SUM(C10:E10) -> 60
A11: 4 | B11: ECK | C11: 0 | D11: 8 | E11: 1 | F11: =SUM(C11:E11) -> 9
A12: 5 | B12: ECBAPT | C12: 0 | D12: 0 | E12: 0 | F12: =SUM(C12:E12) -> 0
A13: 6 | B13: ECADV | C13: 0 | D13: 4 | E13: 3 | F13: =SUM(C13:E13) -> 7
A14: 7 | B14: PRIVEE | C14: 0 | D14: 0 | E14: 0 | F14: =SUM(C14:E14) -> 0
A15: TOTAL | C15: =SUM(C8:C14) -> 5 | D15: =SUM(D8:D14) -> 165 | E15: =SUM(E8:E14) -> 65 | F15: =SUM(F8:F14) -> 235
A17: ENSEIGNEMENT PRE-PRIMAIRE
A18: Tableau 2 : Nombre de classes organisées par année d’études et regime de gestion
A19: N° | B19: Niveau d’enseignement et Régime de Gestion | C19: 1ère année | D19: 2è année | E19: 3è annnée | F19: TOTAL
A20: 1 | B20: ENC | C20: 3 | D20: 3 | E20: 3 | F20: =SUM(C20:E20) -> 9
A21: 2 | B21: ECC | C21: 1 | D21: 1 | E21: 1 | F21: =SUM(C21:E21) -> 3
A22: 3 | B22: ECP | C22: 1 | D22: 1 | E22: 1 | F22: =SUM(C22:E22) -> 3
A23: 4 | B23: ECK | C23: 0 | D23: 0 | E23: 0 | F23: =SUM(C23:E23) -> 0
A24: 5 | B24: ECBAPT | C24: 0 | D24: 0 | E24: 0 | F24: =SUM(C24:E24) -> 0
A25: 6 | B25: ECADV | C25: 0 | D25: 0 | E25: 0 | F25: =SUM(C25:E25) -> 0
A26: 7 | B26: PRIVEE | C26: 0 | D26: 0 | E26: 0 | F26: =SUM(C26:E26) -> 0
A27: TOTAL | C27: =SUM(C20:C26) -> 5 | D27: =SUM(D20:D26) -> 5 | E27: =SUM(E20:E26) -> 5 | F27: =SUM(F20:F26) -> 15
A29: Tableau : Enfants inscrits par année d’études, sexe et regime de gestion
A30: N° | B30: Niveau d’enseignement et Régime de Gestion | C30: 1ère Année | E30: 2è Année | G30: 3è Année | I30: TOTAL
C31: G | D31: F | E31: G | F31: F | G31: G | H31: F | I31: G | J31: F | K31: GF
A32: 1 | B32: ENC | C32: 25 | D32: 17 | E32: 23 | F32: 22 | G32: 21 | H32: 21 | I32: =SUM(C32+E32+G32) -> 69 | J32: 60 | K32: 129 | M32: =SUM(D32+F32+H32) -> 60
A33: 2 | B33: ECC | C33: 15 | D33: 10 | E33: 10 | F33: 8 | G33: 9 | H33: 12 | I33: =SUM(C33+E33+G33) -> 34 | J33: 30 | K33: 64 | M33: =SUM(D33+F33+H33) -> 30
A34: 3 | B34: ECP | C34: 7 | D34: 8 | E34: 6 | F34: 9 | G34: 6 | H34: 10 | I34: =SUM(C34+E34+G34) -> 19 | J34: 27 | K34: 46 | M34: =SUM(D34+F34+H34) -> 27
A35: 4 | B35: ECK | C35: 0 | D35: 0 | E35: 0 | F35: 0 | G35: 0 | H35: 0 | I35: =SUM(C35+E35+G35) -> 0 | J35: 0 | K35: 0 | M35: =SUM(D35+F35+H35) -> 0
A36: 5 | B36: ECBAPT | C36: 0 | D36: 0 | E36: 0 | F36: 0 | G36: 0 | H36: 0 | I36: =SUM(C36+E36+G36) -> 0 | J36: 0 | K36: 0 | M36: =SUM(D36+F36+H36) -> 0
A37: 6 | B37: ECADV | C37: 0 | D37: 0 | E37: 0 | F37: 0 | G37: 0 | H37: 0 | I37: =SUM(C37+E37+G37) -> 0 | J37: 0 | K37: 0 | M37: =SUM(D37+F37+H37) -> 0
A38: 7 | B38: PRIVEE | C38: 0 | D38: 0 | E38: 0 | F38: 0 | G38: 0 | H38: 0 | I38: =SUM(C38+E38+G38) -> 0 | J38: 0 | K38: 0 | M38: =SUM(D38+F38+H38) -> 0
A39: TOTAL | C39: =SUM(C32:C38) -> 47 | D39: =SUM(D32:D38) -> 35 | E39: =SUM(E32:E38) -> 39 | F39: =SUM(F32:F38) -> 39 | G39: =SUM(G32:G38) -> 36 | H39: =SUM(H32:H38) -> 43 | I39: =SUM(I32:I38) -> 122 | J39: =SUM(J32:J38) -> 117 | K39: =SUM(K32:K38) -> 239 | M39: =SUM(D39+F39+H39) -> 117
A41: Tableau 4 : Educateurs (trices) par qualification, sexe et régime de gestion
A42: N° | B42: Niveau d’enseignement et Régime de Gestion | C42: EAP, D3 | E42: D4 | G42: EM | I42: D6 | K42: AUTRE | M42: TOTAL
C43: H | D43: F | E43: H | F43: F | G43: H | H43: F | I43: H | J43: F | K43: H | L43: F | M43: H | N43: F | O43: HF
...

Sheet PWETO
A1: COLLECTE RAPIDE DES DONNEES STATISTIQUES SCOLAIRES DES PARAMETRES ESSENTIELS
A2: TABLEAU SYNTHESE
A3: SOUS-DIVISION EDUCATIONNELLE :…………………………………………………………………………………. | D3: PWETO
A4: PROVINCE EDUCATIONNELLE :…………………………………………………………………………………. | D4: HAUT-KATANGA 2
A5: PROVINCE ADMINISTRATIVE :…………………………………………………………………………………. | D5: HAUT-KATANGA
A6: Tableau 1 : Nombre d’Etablissements scolaires par Niveau d’enseignement et Regime de Gestion
A7: N° | B7: Niveau d’enseignement et Régime de Gestion | C7: PRE-PRIMAIRE | D7: PRIMAIRE | E7: SECONDAIRE | F7: TOTAL
A8: 1 | B8: ENC | C8: 0 | D8: 20 | E8: 11 | F8: 31
A9: 2 | B9: ECC | C9: 1 | D9: 42 | E9: 15 | F9: 58
A10: 3 | B10: ECP | C10: 0 | D10: 79 | E10: 37 | F10: 116
A11: 4 | B11: ECK | C11: 0 | D11: 9 | E11: 4 | F11: 13
A12: 5 | B12: ECBAPT | C12: 0 | D12: 0 | E12: 0 | F12: 0
A13: 6 | B13: ECADV | C13: 0 | D13: 3 | E13: 1 | F13: 4
A14: 7 | B14: PRIVEE | C14: 0 | D14: 5 | E14: 3 | F14: 8
A15: TOTAL | C15: =SUM(C8:C14) -> 1 | D15: =SUM(D8:D14) -> 158 | E15: =SUM(E8:E14) -> 71 | F15: =SUM(F8:F14) -> 230
A17: ENSEIGNEMENT PRE-PRIMAIRE
A18: Tableau 2 : Nombre de classes organisées par année d’études et regime de gestion
A19: N° | B19: Niveau d’enseignement et Régime de Gestion | C19: 1ère année | D19: 2è année | E19: 3è annnée | F19: TOTAL
A20: 1 | B20: ENC | C20: 0 | D20: 0 | E20: 0 | F20: 0
A21: 2 | B21: ECC | C21: 1 | D21: 1 | E21: 1 | F21: 3
A22: 3 | B22: ECP | C22: 0 | D22: 0 | E22: 0 | F22: 0
A23: 4 | B23: ECK | C23: 0 | D23: 0 | E23: 0 | F23: 0
A24: 5 | B24: ECBAPT | C24: 0 | D24: 0 | E24: 0 | F24: 0
A25: 6 | B25: ECADV | C25: 0 | D25: 0 | E25: 0 | F25: 0
A26: 7 | B26: PRIVEE | C26: 0 | D26: 0 | E26: 0 | F26: 0
A27: TOTAL | C27: =SUM(C20:C26) -> 1 | D27: =SUM(D20:D26) -> 1 | E27: =SUM(E20:E26) -> 1 | F27: =SUM(F20:F26) -> 3
A29: Tableau : Enfants inscrits par année d’études, sexe et regime de gestion
A30: N° | B30: Niveau d’enseignement et Régime de Gestion | C30: 1ère Année | E30: 2è Année | G30: 3è Année | I30: TOTAL
C31: G | D31: F | E31: G | F31: F | G31: G | H31: F | I31: G | J31: F | K31: GF
A32: 1 | B32: ENC | C32: 0 | D32: 0 | E32: 0 | F32: 0 | G32: 0 | H32: 0 | I32: =G32+E32+C32 -> 0 | J32: =H32+F32+D32 -> 0 | K32: =J32+I32 -> 0
A33: 2 | B33: ECC | C33: 30 | D33: 23 | E33: 20 | F33: 27 | G33: 12 | H33: 10 | I33: =G33+E33+C33 -> 62 | J33: =H33+F33+D33 -> 60 | K33: =J33+I33 -> 122
A34: 3 | B34: ECP | C34: 0 | D34: 0 | E34: 0 | F34: 0 | G34: 0 | H34: 0 | I34: =G34+E34+C34 -> 0 | J34: =H34+F34+D34 -> 0 | K34: =J34+I34 -> 0
A35: 4 | B35: ECK | C35: 0 | D35: 0 | E35: 0 | F35: 0 | G35: 0 | H35: 0 | I35: =G35+E35+C35 -> 0 | J35: =H35+F35+D35 -> 0 | K35: =J35+I35 -> 0
A36: 5 | B36: ECBAPT | C36: 0 | D36: 0 | E36: 0 | F36: 0 | G36: 0 | H36: 0 | I36: =G36+E36+C36 -> 0 | J36: =H36+F36+D36 -> 0 | K36: =J36+I36 -> 0
A37: 6 | B37: ECADV | C37: 0 | D37: 0 | E37: 0 | F37: 0 | G37: 0 | H37: 0 | I37: =G37+E37+C37 -> 0 | J37: =H37+F37+D37 -> 0 | K37: =J37+I37 -> 0
A38: 7 | B38: PRIVEE | C38: 0 | D38: 0 | E38: 0 | F38: 0 | G38: 0 | H38: 0 | I38: =G38+E38+C38 -> 0 | J38: =H38+F38+D38 -> 0 | K38: =J38+I38 -> 0
A39: TOTAL | C39: =SUM(C32:C38) -> 30 | D39: =SUM(D32:D38) -> 23 | E39: =SUM(E32:E38) -> 20 | F39: =SUM(F32:F38) -> 27 | G39: =SUM(G32:G38) -> 12 | H39: =SUM(H32:H38) -> 10 | I39: =SUM(I32:I38) -> 62 | J39: =SUM(J32:J38) -> 60 | K39: =SUM(K32:K38) -> 122
A41: Tableau 4 : Educateurs (trices) par qualification, sexe et régime de gestion
A42: N° | B42: Niveau d’enseignement et Régime de Gestion | C42: EAP, D3 | E42: D4 | G42: EM | I42: D6 | K42: AUTRE | M42: TOTAL
C43: H | D43: F | E43: H | F43: F | G43: H | H43: F | I43: H | J43: F | K43: H | L43: F | M43: H | N43: F | O43: HF
...

Sheet SYNTHESE_HKAT_2
A1: COLLECTE RAPIDE DES DONNEES STATISTIQUES SCOLAIRES DES PARAMETRES ESSENTIELS
A2: TABLEAU SYNTHESE
A3: SOUS-DIVISION EDUCATIONNELLE :…………………………………………………………………………………. | D3: PWETO
A4: PROVINCE EDUCATIONNELLE :…………………………………………………………………………………. | D4: HAUT-KATANGA 2
A5: PROVINCE ADMINISTRATIVE :…………………………………………………………………………………. | D5: HAUT-KATANGA
A6: Tableau 1 : Nombre d’Etablissements scolaires par Niveau d’enseignement et Regime de Gestion
A7: N° | B7: Niveau d’enseignement et Régime de Gestion | C7: PRE-PRIMAIRE | D7: PRIMAIRE | E7: SECONDAIRE | F7: TOTAL
A8: 1 | B8: ENC | C8: =PWETO!C8+MITWABA!C8+KILWA!C8+KASENGA!C9 -> 3 | D8: =PWETO!D8+MITWABA!D8+KILWA!D8+KASENGA!D9 -> 77 | E8: =PWETO!E8+MITWABA!E8+KILWA!E8+KASENGA!E9 -> 59 | F8: =SUM(C8:E8) -> 139
A9: 2 | B9: ECC | C9: =PWETO!C9+MITWABA!C9+KILWA!C9+KASENGA!C10 -> 7 | D9: =PWETO!D9+MITWABA!D9+KILWA!D9+KASENGA!D10 -> 248 | E9: =PWETO!E9+MITWABA!E9+KILWA!E9+KASENGA!E10 -> 102 | F9: =SUM(C9:E9) -> 357
A10: 3 | B10: ECP | C10: =PWETO!C10+MITWABA!C10+KILWA!C10+KASENGA!C11 -> 2 | D10: =PWETO!D10+MITWABA!D10+KILWA!D10+KASENGA!D11 -> 283 | E10: =PWETO!E10+MITWABA!E10+KILWA!E10+KASENGA!E11 -> 135 | F10: =SUM(C10:E10) -> 420
A11: 4 | B11: ECK | C11: =PWETO!C11+MITWABA!C11+KILWA!C11+KASENGA!C12 -> 0 | D11: =PWETO!D11+MITWABA!D11+KILWA!D11+KASENGA!D12 -> 21 | E11: =PWETO!E11+MITWABA!E11+KILWA!E11+KASENGA!E12 -> 7 | F11: =SUM(C11:E11) -> 28
A12: 5 | B12: ECBAPT | C12: =PWETO!C12+MITWABA!C12+KILWA!C12+KASENGA!C13 -> 0 | D12: =PWETO!D12+MITWABA!D12+KILWA!D12+KASENGA!D13 -> 0 | E12: =PWETO!E12+MITWABA!E12+KILWA!E12+KASENGA!E13 -> 1 | F12: =SUM(C12:E12) -> 1
A13: 6 | B13: ECADV | C13: =PWETO!C13+MITWABA!C13+KILWA!C13+KASENGA!C14 -> 0 | D13: =PWETO!D13+MITWABA!D13+KILWA!D13+KASENGA!D14 -> 9 | E13: =PWETO!E13+MITWABA!E13+KILWA!E13+KASENGA!E14 -> 6 | F13: =SUM(C13:E13) -> 15
A14: 7 | B14: PRIVEE | C14: =PWETO!C14+MITWABA!C14+KILWA!C14+KASENGA!C15 -> 1 | D14: =PWETO!D14+MITWABA!D14+KILWA!D14+KASENGA!D15 -> 10 | E14: =PWETO!E14+MITWABA!E14+KILWA!E14+KASENGA!E15 -> 6 | F14: =SUM(C14:E14) -> 17
A15: TOTAL | C15: =SUM(C8:C14) -> 13 | D15: =SUM(D8:D14) -> 648 | E15: =SUM(E8:E14) -> 316 | F15: =SUM(F8:F14) -> 977
A17: ENSEIGNEMENT PRE-PRIMAIRE
A18: Tableau 2 : Nombre de classes organisées par année d’études et regime de gestion
A19: N° | B19: Niveau d’enseignement et Régime de Gestion | C19: 1ère année | D19: 2è année | E19: 3è annnée | F19: TOTAL
A20: 1 | B20: ENC | C20: =PWETO!C20+MITWABA!C20+KILWA!C20+KASENGA!C21 -> 3 | D20: =PWETO!D20+MITWABA!D20+KILWA!D20+KASENGA!D21 -> 3 | E20: =PWETO!E20+MITWABA!E20+KILWA!E20+KASENGA!E21 -> 3 | F20: =SUM(C20:E20) -> 9
A21: 2 | B21: ECC | C21: =PWETO!C21+MITWABA!C21+KILWA!C21+KASENGA!C22 -> 8 | D21: =PWETO!D21+MITWABA!D21+KILWA!D21+KASENGA!D22 -> 7 | E21: =PWETO!E21+MITWABA!E21+KILWA!E21+KASENGA!E22 -> 7 | F21: =SUM(C21:E21) -> 22
A22: 3 | B22: ECP | C22: =PWETO!C22+MITWABA!C22+KILWA!C22+KASENGA!C23 -> 3 | D22: =PWETO!D22+MITWABA!D22+KILWA!D22+KASENGA!D23 -> 3 | E22: =PWETO!E22+MITWABA!E22+KILWA!E22+KASENGA!E23 -> 1 | F22: =SUM(C22:E22) -> 7
A23: 4 | B23: ECK | C23: =PWETO!C23+MITWABA!C23+KILWA!C23+KASENGA!C24 -> 0 | D23: =PWETO!D23+MITWABA!D23+KILWA!D23+KASENGA!D24 -> 0 | E23: =PWETO!E23+MITWABA!E23+KILWA!E23+KASENGA!E24 -> 0 | F23: =SUM(C23:E23) -> 0
A24: 5 | B24: ECBAPT | C24: =PWETO!C24+MITWABA!C24+KILWA!C24+KASENGA!C25 -> 0 | D24: =PWETO!D24+MITWABA!D24+KILWA!D24+KASENGA!D25 -> 0 | E24: =PWETO!E24+MITWABA!E24+KILWA!E24+KASENGA!E25 -> 0 | F24: =SUM(C24:E24) -> 0
A25: 6 | B25: ECADV | C25: =PWETO!C25+MITWABA!C25+KILWA!C25+KASENGA!C26 -> 0 | D25: =PWETO!D25+MITWABA!D25+KILWA!D25+KASENGA!D26 -> 0 | E25: =PWETO!E25+MITWABA!E25+KILWA!E25+KASENGA!E26 -> 0 | F25: =SUM(C25:E25) -> 0
A26: 7 | B26: PRIVEE | C26: =PWETO!C26+MITWABA!C26+KILWA!C26+KASENGA!C27 -> 1 | D26: =PWETO!D26+MITWABA!D26+KILWA!D26+KASENGA!D27 -> 1 | E26: =PWETO!E26+MITWABA!E26+KILWA!E26+KASENGA!E27 -> 1 | F26: =SUM(C26:E26) -> 3
A27: TOTAL | C27: =SUM(C20:C26) -> 15 | D27: =SUM(D20:D26) -> 14 | E27: =SUM(E20:E26) -> 12 | F27: =SUM(F20:F26) -> 41
A29: Tableau : Enfants inscrits par année d’études, sexe et regime de gestion
A30: N° | B30: Niveau d’enseignement et Régime de Gestion | C30: 1ère Année | E30: 2è Année | G30: 3è Année | I30: TOTAL
C31: G | D31: F | E31: G | F31: F | G31: G | H31: F | I31: G | J31: F | K31: GF
A32: 1 | B32: ENC | C32: =PWETO!C32+MITWABA!C32+KILWA!C32+KASENGA!C33 -> 25 | D32: =PWETO!D32+MITWABA!D32+KILWA!D32+KASENGA!D33 -> 17 | E32: =PWETO!E32+MITWABA!E32+KILWA!E32+KASENGA!E33 -> 23 | F32: =PWETO!F32+MITWABA!F32+KILWA!F32+KASENGA!F33 -> 22 | G32: =PWETO!G32+MITWABA!G32+KILWA!G32+KASENGA!G33 -> 21 | H32: =PWETO!H32+MITWABA!H32+KILWA!H32+KASENGA!H33 -> 21 | I32: =G32+E32+C32 -> 69 | J32: =H32+F32+D32 -> 60 | K32: =J32+I32 -> 129
A33: 2 | B33: ECC | C33: =PWETO!C33+MITWABA!C33+KILWA!C33+KASENGA!C34 -> 109 | D33: =PWETO!D33+MITWABA!D33+KILWA!D33+KASENGA!D34 -> 107 | E33: =PWETO!E33+MITWABA!E33+KILWA!E33+KASENGA!E34 -> 96 | F33: =PWETO!F33+MITWABA!F33+KILWA!F33+KASENGA!F34 -> 108 | G33: =PWETO!G33+MITWABA!G33+KILWA!G33+KASENGA!G34 -> 66 | H33: =PWETO!H33+MITWABA!H33+KILWA!H33+KASENGA!H34 -> 71 | I33: =G33+E33+C33 -> 271 | J33: =H33+F33+D33 -> 286 | K33: =J33+I33 -> 557
A34: 3 | B34: ECP | C34: =PWETO!C34+MITWABA!C34+KILWA!C34+KASENGA!C35 -> 15 | D34: =PWETO!D34+MITWABA!D34+KILWA!D34+KASENGA!D35 -> 18 | E34: =PWETO!E34+MITWABA!E34+KILWA!E34+KASENGA!E35 -> 13 | F34: =PWETO!F34+MITWABA!F34+KILWA!F34+KASENGA!F35 -> 14 | G34: =PWETO!G34+MITWABA!G34+KILWA!G34+KASENGA!G35 -> 15 | H34: =PWETO!H34+MITWABA!H34+KILWA!H34+KASENGA!H35 -> 14 | I34: =G34+E34+C34 -> 43 | J34: =H34+F34+D34 -> 46 | K34: =J34+I34 -> 89
A35: 4 | B35: ECK | C35: =PWETO!C35+MITWABA!C35+KILWA!C35+KASENGA!C36 -> 0 | D35: =PWETO!D35+MITWABA!D35+KILWA!D35+KASENGA!D36 -> 0 | E35: =PWETO!E35+MITWABA!E35+KILWA!E35+KASENGA!E36 -> 0 | F35: =PWETO!F35+MITWABA!F35+KILWA!F35+KASENGA!F36 -> 0 | G35: =PWETO!G35+MITWABA!G35+KILWA!G35+KASENGA!G36 -> 0 | H35: =PWETO!H35+MITWABA!H35+KILWA!H35+KASENGA!H36 -> 0 | I35: =G35+E35+C35 -> 0 | J35: =H35+F35+D35 -> 0 | K35: =J35+I35 -> 0
A36: 5 | B36: ECBAPT | C36: =PWETO!C36+MITWABA!C36+KILWA!C36+KASENGA!C37 -> 0 | D36: =PWETO!D36+MITWABA!D36+KILWA!D36+KASENGA!D37 -> 0 | E36: =PWETO!E36+MITWABA!E36+KILWA!E36+KASENGA!E37 -> 0 | F36: =PWETO!F36+MITWABA!F36+KILWA!F36+KASENGA!F37 -> 0 | G36: =PWETO!G36+MITWABA!G36+KILWA!G36+KASENGA!G37 -> 0 | H36: =PWETO!H36+MITWABA!H36+KILWA!H36+KASENGA!H37 -> 0 | I36: =G36+E36+C36 -> 0 | J36: =H36+F36+D36 -> 0 | K36: =J36+I36 -> 0
A37: 6 | B37: ECADV | C37: =PWETO!C37+MITWABA!C37+KILWA!C37+KASENGA!C38 -> 0 | D37: =PWETO!D37+MITWABA!D37+KILWA!D37+KASENGA!D38 -> 0 | E37: =PWETO!E37+MITWABA!E37+KILWA!E37+KASENGA!E38 -> 0 | F37: =PWETO!F37+MITWABA!F37+KILWA!F37+KASENGA!F38 -> 0 | G37: =PWETO!G37+MITWABA!G37+KILWA!G37+KASENGA!G38 -> 0 | H37: =PWETO!H37+MITWABA!H37+KILWA!H37+KASENGA!H38 -> 0 | I37: =G37+E37+C37 -> 0 | J37: =H37+F37+D37 -> 0 | K37: =J37+I37 -> 0
A38: 7 | B38: PRIVEE | C38: =PWETO!C38+MITWABA!C38+KILWA!C38+KASENGA!C39 -> 5 | D38: =PWETO!D38+MITWABA!D38+KILWA!D38+KASENGA!D39 -> 4 | E38: =PWETO!E38+MITWABA!E38+KILWA!E38+KASENGA!E39 -> 3 | F38: =PWETO!F38+MITWABA!F38+KILWA!F38+KASENGA!F39 -> 2 | G38: =PWETO!G38+MITWABA!G38+KILWA!G38+KASENGA!G39 -> 1 | H38: =PWETO!H38+MITWABA!H38+KILWA!H38+KASENGA!H39 -> 3 | I38: =G38+E38+C38 -> 9 | J38: =H38+F38+D38 -> 9 | K38: =J38+I38 -> 18
A39: TOTAL | C39: =SUM(C32:C38) -> 154 | D39: =SUM(D32:D38) -> 146 | E39: =SUM(E32:E38) -> 135 | F39: =SUM(F32:F38) -> 146 | G39: =SUM(G32:G38) -> 103 | H39: =SUM(H32:H38) -> 109 | I39: =SUM(I32:I38) -> 392 | J39: =SUM(J32:J38) -> 401 | K39: =SUM(K32:K38) -> 793
A41: Tableau 4 : Educateurs (trices) par qualification, sexe et régime de gestion
A42: N° | B42: Niveau d’enseignement et Régime de Gestion | C42: EAP, D3 | E42: D4 | G42: EM | I42: D6 | K42: AUTRE | M42: TOTAL
C43: H | D43: F | E43: H | F43: F | G43: H | H43: F | I43: H | J43: F | K43: H | L43: F | M43: H | N43: F | O43: HF
...

Sheet SYNTHESE GENERALE
A1: COLLECTE RAPIDE DES DONNEES STATISTIQUES SCOLAIRES DES PARAMETRES ESSENTIELS
A2: TABLEAU SYNTHESE
A3: SOUS-DIVISION EDUCATIONNELLE :…………………………………………………………………………………. | D3: KASENGA, KILWA, MITWABA, PWETO
A4: PROVINCE EDUCATIONNELLE :…………………………………………………………………………………. | D4: HAUT-KATANGA 2
A5: PROVINCE ADMINISTRATIVE :…………………………………………………………………………………. | D5: HAUT-KATANGA
A6: Tableau 1 : Nombre d’Etablissements scolaires par Niveau d’enseignement et Regime de Gestion
A7: N° | B7: Niveau d’enseignement et Régime de Gestion | C7: PRE-PRIMAIRE | D7: PRIMAIRE | E7: SECONDAIRE | F7: TOTAL
A8: 1 | B8: ENC | C8: 3 | D8: 77 | E8: 59 | F8: 139
A9: 2 | B9: ECC | C9: 7 | D9: 248 | E9: 102 | F9: 357
A10: 3 | B10: ECP | C10: 2 | D10: 283 | E10: 135 | F10: 420
A11: 4 | B11: ECK | C11: 0 | D11: 21 | E11: 7 | F11: 28
A12: 5 | B12: ECBAPT | C12: 0 | D12: 0 | E12: 1 | F12: 1
A13: 6 | B13: ECADV | C13: 0 | D13: 9 | E13: 6 | F13: 15
A14: 7 | B14: PRIVEE | C14: 1 | D14: 10 | E14: 6 | F14: 17
A15: TOTAL | C15: 13 | D15: 648 | E15: 316 | F15: 997
A17: ENSEIGNEMENT PRE-PRIMAIRE
A18: Tableau 2 : Nombre de classes organisées par année d’études et regime de gestion
A19: N° | B19: Niveau d’enseignement et Régime de Gestion | C19: 1ère année | D19: 2è année | E19: 3è annnée | F19: TOTAL
A20: 1 | B20: ENC | F20: 9
A21: 2 | B21: ECC | F21: 22
A22: 3 | B22: ECP | F22: 7
A23: 4 | B23: ECK | F23: 0
A24: 5 | B24: ECBAPT | F24: 0
A25: 6 | B25: ECADV | F25: 0
A26: 7 | B26: PRIVEE | F26: 3
A27: TOTAL | F27: 41
A29: Tableau : Enfants inscrits par année d’études, sexe et regime de gestion
A30: N° | B30: Niveau d’enseignement et Régime de Gestion | C30: 1ère Année | E30: 2è Année | G30: 3è Année | I30: TOTAL
C31: G | D31: F | E31: G | F31: F | G31: G | H31: F | I31: G | J31: F | K31: GF
A32: 1 | B32: ENC | J32: 60 | K32: 129
A33: 2 | B33: ECC | J33: 282 | K33: 570
A34: 3 | B34: ECP | J34: 42 | K34: 76
A35: 4 | B35: ECK | J35: 0 | K35: 0
A36: 5 | B36: ECBAPT | J36: 0 | K36: 0
A37: 6 | B37: ECADV | J37: 0 | K37: 0
A38: 7 | B38: PRIVEE | J38: 9 | K38: 18
A39: TOTAL | J39: 393 | K39: 793
A41: Tableau 4 : Educateurs (trices) par qualification, sexe et régime de gestion
A42: N° | B42: Niveau d’enseignement et Régime de Gestion | C42: EAP, D3 | E42: D4 | G42: EM | I42: D6 | K42: AUTRE | M42: TOTAL
C43: H | D43: F | E43: H | F43: F | G43: H | H43: F | I43: H | J43: F | K43: H | L43: F | M43: H | N43: F | O43: HF
...
